/vortexfs1/scratch/msantos/gp_plankton_model/slurm_scripts/sweep
pn031
Fri Nov  4 11:38:16 EDT 2022
training model_spectral
3: wandb: Currently logged in as: mirasantos (mira_thesis). Use `wandb login --relogin` to force relogin
0: wandb: Currently logged in as: mirasantos (mira_thesis). Use `wandb login --relogin` to force relogin
4: wandb: Currently logged in as: mirasantos (mira_thesis). Use `wandb login --relogin` to force relogin
1: wandb: Currently logged in as: mirasantos (mira_thesis). Use `wandb login --relogin` to force relogin
2: wandb: Currently logged in as: mirasantos (mira_thesis). Use `wandb login --relogin` to force relogin
4: Traceback (most recent call last):
4:   File "/vortexfs1/home/msantos/.conda/envs/gpytorch/lib/python3.9/runpy.py", line 197, in _run_module_as_main
4:     return _run_code(code, main_globals, None,
4:   File "/vortexfs1/home/msantos/.conda/envs/gpytorch/lib/python3.9/runpy.py", line 87, in _run_code
4:     exec(code, run_globals)
4:   File "/vortexfs1/scratch/msantos/gp_plankton_model/train/sweep.py", line 80, in <module>
4:     dfsubset, X_train, y_train, X_test, y_test = load_test_train()
4:   File "/vortexfs1/scratch/msantos/gp_plankton_model/train/sweep.py", line 22, in load_test_train
4:     torch.save(X, config["split_folder"] + config["dependent"] + "X_dataset.pt")
4:   File "/vortexfs1/home/msantos/.conda/envs/gpytorch/lib/python3.9/site-packages/torch/serialization.py", line 376, in save
4:     with _open_file_like(f, 'wb') as opened_file:
4:   File "/vortexfs1/home/msantos/.conda/envs/gpytorch/lib/python3.9/site-packages/torch/serialization.py", line 230, in _open_file_like
4:     return _open_file(name_or_buffer, mode)
4:   File "/vortexfs1/home/msantos/.conda/envs/gpytorch/lib/python3.9/site-packages/torch/serialization.py", line 211, in __init__
4:     super(_open_file, self).__init__(open(name, mode))
4: FileNotFoundError: [Errno 2] No such file or directory: '/home/mira/PycharmProjects/gp_plankton_model/datasets/split/synconcX_dataset.pt'
3: Traceback (most recent call last):
3:   File "/vortexfs1/home/msantos/.conda/envs/gpytorch/lib/python3.9/runpy.py", line 197, in _run_module_as_main
3:     return _run_code(code, main_globals, None,
3:   File "/vortexfs1/home/msantos/.conda/envs/gpytorch/lib/python3.9/runpy.py", line 87, in _run_code
3:     exec(code, run_globals)
3:   File "/vortexfs1/scratch/msantos/gp_plankton_model/train/sweep.py", line 80, in <module>
3:     dfsubset, X_train, y_train, X_test, y_test = load_test_train()
3:   File "/vortexfs1/scratch/msantos/gp_plankton_model/train/sweep.py", line 22, in load_test_train
3:     torch.save(X, config["split_folder"] + config["dependent"] + "X_dataset.pt")
3:   File "/vortexfs1/home/msantos/.conda/envs/gpytorch/lib/python3.9/site-packages/torch/serialization.py", line 376, in save
3:     with _open_file_like(f, 'wb') as opened_file:
3:   File "/vortexfs1/home/msantos/.conda/envs/gpytorch/lib/python3.9/site-packages/torch/serialization.py", line 230, in _open_file_like
3:     return _open_file(name_or_buffer, mode)
3:   File "/vortexfs1/home/msantos/.conda/envs/gpytorch/lib/python3.9/site-packages/torch/serialization.py", line 211, in __init__
3:     super(_open_file, self).__init__(open(name, mode))
3: FileNotFoundError: [Errno 2] No such file or directory: '/home/mira/PycharmProjects/gp_plankton_model/datasets/split/synconcX_dataset.pt'
0: Traceback (most recent call last):
0:   File "/vortexfs1/home/msantos/.conda/envs/gpytorch/lib/python3.9/runpy.py", line 197, in _run_module_as_main
0:     return _run_code(code, main_globals, None,
0:   File "/vortexfs1/home/msantos/.conda/envs/gpytorch/lib/python3.9/runpy.py", line 87, in _run_code
0:     exec(code, run_globals)
0:   File "/vortexfs1/scratch/msantos/gp_plankton_model/train/sweep.py", line 80, in <module>
0:     dfsubset, X_train, y_train, X_test, y_test = load_test_train()
0:   File "/vortexfs1/scratch/msantos/gp_plankton_model/train/sweep.py", line 22, in load_test_train
0:     torch.save(X, config["split_folder"] + config["dependent"] + "X_dataset.pt")
0:   File "/vortexfs1/home/msantos/.conda/envs/gpytorch/lib/python3.9/site-packages/torch/serialization.py", line 376, in save
0:     with _open_file_like(f, 'wb') as opened_file:
0:   File "/vortexfs1/home/msantos/.conda/envs/gpytorch/lib/python3.9/site-packages/torch/serialization.py", line 230, in _open_file_like
0:     return _open_file(name_or_buffer, mode)
0:   File "/vortexfs1/home/msantos/.conda/envs/gpytorch/lib/python3.9/site-packages/torch/serialization.py", line 211, in __init__
0:     super(_open_file, self).__init__(open(name, mode))
0: FileNotFoundError: [Errno 2] No such file or directory: '/home/mira/PycharmProjects/gp_plankton_model/datasets/split/synconcX_dataset.pt'
1: Traceback (most recent call last):
1:   File "/vortexfs1/home/msantos/.conda/envs/gpytorch/lib/python3.9/runpy.py", line 197, in _run_module_as_main
1:     return _run_code(code, main_globals, None,
1:   File "/vortexfs1/home/msantos/.conda/envs/gpytorch/lib/python3.9/runpy.py", line 87, in _run_code
1:     exec(code, run_globals)
1:   File "/vortexfs1/scratch/msantos/gp_plankton_model/train/sweep.py", line 80, in <module>
1:     dfsubset, X_train, y_train, X_test, y_test = load_test_train()
1:   File "/vortexfs1/scratch/msantos/gp_plankton_model/train/sweep.py", line 22, in load_test_train
1:     torch.save(X, config["split_folder"] + config["dependent"] + "X_dataset.pt")
1:   File "/vortexfs1/home/msantos/.conda/envs/gpytorch/lib/python3.9/site-packages/torch/serialization.py", line 376, in save
1:     with _open_file_like(f, 'wb') as opened_file:
1:   File "/vortexfs1/home/msantos/.conda/envs/gpytorch/lib/python3.9/site-packages/torch/serialization.py", line 230, in _open_file_like
1:     return _open_file(name_or_buffer, mode)
1:   File "/vortexfs1/home/msantos/.conda/envs/gpytorch/lib/python3.9/site-packages/torch/serialization.py", line 211, in __init__
1:     super(_open_file, self).__init__(open(name, mode))
1: FileNotFoundError: [Errno 2] No such file or directory: '/home/mira/PycharmProjects/gp_plankton_model/datasets/split/synconcX_dataset.pt'
2: Traceback (most recent call last):
2:   File "/vortexfs1/home/msantos/.conda/envs/gpytorch/lib/python3.9/runpy.py", line 197, in _run_module_as_main
2:     return _run_code(code, main_globals, None,
2:   File "/vortexfs1/home/msantos/.conda/envs/gpytorch/lib/python3.9/runpy.py", line 87, in _run_code
2:     exec(code, run_globals)
2:   File "/vortexfs1/scratch/msantos/gp_plankton_model/train/sweep.py", line 80, in <module>
2:     dfsubset, X_train, y_train, X_test, y_test = load_test_train()
2:   File "/vortexfs1/scratch/msantos/gp_plankton_model/train/sweep.py", line 22, in load_test_train
2:     torch.save(X, config["split_folder"] + config["dependent"] + "X_dataset.pt")
2:   File "/vortexfs1/home/msantos/.conda/envs/gpytorch/lib/python3.9/site-packages/torch/serialization.py", line 376, in save
2:     with _open_file_like(f, 'wb') as opened_file:
2:   File "/vortexfs1/home/msantos/.conda/envs/gpytorch/lib/python3.9/site-packages/torch/serialization.py", line 230, in _open_file_like
2:     return _open_file(name_or_buffer, mode)
2:   File "/vortexfs1/home/msantos/.conda/envs/gpytorch/lib/python3.9/site-packages/torch/serialization.py", line 211, in __init__
2:     super(_open_file, self).__init__(open(name, mode))
2: FileNotFoundError: [Errno 2] No such file or directory: '/home/mira/PycharmProjects/gp_plankton_model/datasets/split/synconcX_dataset.pt'
srun: error: pn032: tasks 3-4: Exited with exit code 1
srun: error: pn031: tasks 0-2: Exited with exit code 1
training finished
Fri Nov  4 11:39:33 EDT 2022
