Traceback (most recent call last):
  File "/home/mira/anaconda3/envs/pyro/lib/python3.10/site-packages/pandas/core/indexes/base.py", line 3621, in get_loc
    return self._engine.get_loc(casted_key)
  File "pandas/_libs/index.pyx", line 136, in pandas._libs.index.IndexEngine.get_loc
  File "pandas/_libs/index.pyx", line 163, in pandas._libs.index.IndexEngine.get_loc
  File "pandas/_libs/hashtable_class_helper.pxi", line 5198, in pandas._libs.hashtable.PyObjectHashTable.get_item
  File "pandas/_libs/hashtable_class_helper.pxi", line 5206, in pandas._libs.hashtable.PyObjectHashTable.get_item
KeyError: 'lindex'
The above exception was the direct cause of the following exception:
Traceback (most recent call last):
  File "/home/mira/PycharmProjects/gp_plankton_model/train/train.py", line 133, in <module>
    X = torch.tensor(df[config.predictor].values, dtype=torch.float32)
  File "/home/mira/anaconda3/envs/pyro/lib/python3.10/site-packages/pandas/core/frame.py", line 3505, in __getitem__
    indexer = self.columns.get_loc(key)
  File "/home/mira/anaconda3/envs/pyro/lib/python3.10/site-packages/pandas/core/indexes/base.py", line 3623, in get_loc
    raise KeyError(key) from err
KeyError: 'lindex'